An error occurred: Task <Task pending name='Task-103' coro=<elegantly_launch.<locals>.launch_it() running at /home/runner/step-import/.pythonlibs/lib/python3.12/site-packages/pyvista/trame/jupyter.py:460>> got Future <Future pending cb=[Task.__wakeup()]> attached to a different loop

Traceback: Traceback (most recent call last): File "/home/runner/step-import/main.py", line 165, in <module> temp_html = plotter.export_html('temp.html') ^^^^^^^^^^^^^^^^^^^^^^^^^^^^^^^^ File "/home/runner/step-import/.pythonlibs/lib/python3.12/site-packages/pyvista/plotting/plotter.py", line 638, in export_html data = self.export_vtksz(filename=None) ^^^^^^^^^^^^^^^^^^^^^^^^^^^^^^^^ File "/home/runner/step-import/.pythonlibs/lib/python3.12/site-packages/pyvista/plotting/plotter.py", line 686, in export_vtksz elegantly_launch(pyvista.global_theme.trame.jupyter_server_name) File "/home/runner/step-import/.pythonlibs/lib/python3.12/site-packages/pyvista/trame/jupyter.py", line 465, in elegantly_launch return asyncio.run(launch_it()) ^^^^^^^^^^^^^^^^^^^^^^^^ File "/home/runner/step-import/.pythonlibs/lib/python3.12/site-packages/nest_asyncio.py", line 30, in run return loop.run_until_complete(task) ^^^^^^^^^^^^^^^^^^^^^^^^^^^^^ File "/home/runner/step-import/.pythonlibs/lib/python3.12/site-packages/nest_asyncio.py", line 98, in run_until_complete return f.result() ^^^^^^^^^^ File "/nix/store/nb21sc3npfc8gvazwnrjxpvb5d48jysx-python3-3.12.7/lib/python3.12/asyncio/futures.py", line 203, in result raise self._exception.with_traceback(self._exception_tb) File "/nix/store/nb21sc3npfc8gvazwnrjxpvb5d48jysx-python3-3.12.7/lib/python3.12/asyncio/tasks.py", line 316, in __step_run_and_handle_result result = coro.throw(exc) ^^^^^^^^^^^^^^^ File "/home/runner/step-import/.pythonlibs/lib/python3.12/site-packages/pyvista/trame/jupyter.py", line 460, in launch_it await launch_server(*args, **kwargs).ready File "/nix/store/nb21sc3npfc8gvazwnrjxpvb5d48jysx-python3-3.12.7/lib/python3.12/asyncio/futures.py", line 291, in await yield self # This tells Task to wait for completion. ^^^^^^^^^^ RuntimeError: Task <Task pending name='Task-103' coro=<elegantly_launch.<locals>.launch_it() running at /home/runner/step-import/.pythonlibs/lib/python3.12/site-packages/pyvista/trame/jupyter.py:460>> got Future <Future pending cb=[Task.__wakeup()]> attached to a different loop